{
 "cells": [
  {
   "cell_type": "code",
   "execution_count": null,
   "id": "bfbd828c",
   "metadata": {},
   "outputs": [],
   "source": [
    "Q1.\n",
    "The try-except block is a construct used in programming to handle exceptions or errors that may occur during the execution of a program. It allows you to anticipate and gracefully handle potential errors, ensuring that your program does not abruptly terminate but rather provides appropriate responses or actions when an exception occurs.\n",
    "\n",
    "Here's how the try-except block works:\n",
    "\n",
    "The code that might potentially raise an exception is placed within the \"try\" block.\n",
    "If an exception occurs within the try block, the execution of the try block is immediately stopped, and the program jumps to the except block.\n",
    "The except block contains code that specifies how to handle the exception. It defines the actions to be taken when a particular type of exception is raised.\n",
    "If the exception raised in the try block matches the type of exception specified in the except block, the code within the except block is executed.\n",
    "If the exception raised does not match the type specified in any of the except blocks within the try-except construct, the exception is propagated up the call stack to the nearest outer try-except block, or if none is found, the program terminates with an unhandled exception error.\n",
    "The try-except block provides a way to gracefully handle exceptions and recover from errors during program execution. It allows you to define specific exception-handling code for different types of exceptions, enabling you to take appropriate actions, log errors, display user-friendly messages, or implement alternative logic as needed.\n",
    "\n",
    "Here's an example in Python:\n",
    "    # Code that may raise an exception\n",
    "    result = 10 / 0  # Division by zero raises ZeroDivisionError\n",
    "except ZeroDivisionError:\n",
    "    # Exception handling code for ZeroDivisionError\n",
    "    print(\"Cannot divide by zero!\")\n",
    "except Exception as e:\n",
    "    # Generic exception handling code for other exceptions\n",
    "    print(\"An error occurred:\", str(e))\n",
    "In this example, the code within the try block attempts to perform a division by zero, which raises a ZeroDivisionError. The except block specifically handles this exception by printing a user-friendly error message. If any other type of exception occurs, the generic except block will handle it and display the error message along with the exception details.\n",
    "\n",
    "By using try-except blocks effectively, you can make your programs more robust and resilient to errors, improving their reliability and user experience.\n",
    "\n",
    "Q2.\n",
    "In Python, a basic try-except block is used for exception handling. It allows you to catch and handle exceptions that may occur during the execution of your code. The syntax for a basic try-except block is as follows:\n",
    "\n",
    "    # Code that might raise an exception\n",
    "    # ...\n",
    "except Exception Type:\n",
    "    # Code to handle the exception\n",
    "    # ...\n",
    "Here's a breakdown of the syntax:\n",
    "\n",
    "The try block contains the code that you want to monitor for exceptions.\n",
    "If an exception occurs within the try block, the code execution immediately jumps to the except block.\n",
    "The except block specifies the type of exception you want to catch. You can replace Exception Type with the specific type of exception you want to handle, such as Value Error, Typed Error, Zero DivisionError, or use the more general Exception to catch any type of exception.\n",
    "The code within the except block is executed if an exception of the specified type occurs. You can perform error handling, logging, or any necessary actions within this block.\n",
    "Here's an example that demonstrates the usage of a try-except block:\n",
    "\n",
    "    # Code that might raise an exception\n",
    "    x = int(input(\"Enter a number: \"))\n",
    "    result = 10 / x\n",
    "    print(\"Result:\", result)\n",
    "except ValueError:\n",
    "    print(\"Invalid input. Please enter a valid number.\")\n",
    "except ZeroDivisionError:\n",
    "    print(\"Cannot divide by zero.\")\n",
    "In this example, if the user enters a non-numeric value, a ValueError will be raised and the corresponding error message will be displayed. If the user enters 0, a ZeroDivisionError will be raised, and another error message will be displayed.\n",
    "[28/06, 9:56 am] Krishna Chowdhary: Q3\n",
    "If an exception occurs inside a try block and there is no matching except block to handle that exception, the exception will propagate up the call stack until it is caught by an appropriate exception handler or until it reaches the top level of the program. This process is known as exception propagation or unwinding the stack.\n",
    "\n",
    "If the exception is not caught anywhere in the program, it will typically cause the program to terminate abruptly, and an error message or stack trace may be printed, depending on the programming language and environment. This behavior is often referred to as an \"unhandled exception\" or an \"uncaught exception.\"\n",
    "\n",
    "Here's an example in Python to illustrate this behavior:\n",
    "\n",
    "    # Some code that may raise an exception\n",
    "    result = 10 / 0  # Division by zero, raises ZeroDivision Error\n",
    "except Value Error:\n",
    "    # Exception handler for Value Error\n",
    "    print(\"Value Error occurred\")\n",
    "In this example, the code inside the try block attempts to divide the number 10 by zero, which raises a Zero Division Error. However, the except block specifies a handler for Value Error, not ZeroDivision Error. Since there is no matching handler For Zero value Division, the exception propagates up the call stack. If no outer exception handler catches the exception, the program will terminate with an error message like:\n",
    "\n",
    "vbnet\n",
    "Copy code\n",
    "ZeroDivisionError: division by zero\n",
    "It's generally good practice to provide appropriate exception handlers for expected exceptions and handle any unexpected exceptions gracefully to prevent unexpected program termination.\n",
    "\n",
    " Q4\n",
    "In Python, the try-except block is used for exception handling, allowing you to catch and handle specific types of exceptions that may occur during the execution of your code. The difference between using a bare except block and specifying a specific exception type lies in the level of control and granularity you have over the exceptions that are caught.\n",
    "\n",
    "Bare except block:\n",
    "A bare except block catches all exceptions that occur within the try block. It does not differentiate between different exception types, which can make it harder to determine the specific cause of the exception. It is generally considered bad practice to use a bare except block because it can hide errors and make debugging more difficult. It's recommended to use specific exception types whenever possible.\n",
    "Example\n",
    "    # Some code that may raise an exception\n",
    "    pass\n",
    "except:\n",
    "    # Handling code for any exception\n",
    "    pass\n",
    "Specifying a specific exception type:\n",
    "When you specify a specific exception type in the except block, it will only catch exceptions of that particular type. This allows you to handle different exceptions in different ways, providing more control and clarity in your code.\n",
    "Example\n",
    "    # Some code that may raise an exception\n",
    "    pass\n",
    "except ValueError:\n",
    "    # Handling code specific to ValueError\n",
    "    pass\n",
    "except KeyError:\n",
    "    # Handling code specific to KeyError\n",
    "    pass\n",
    "Yes, you can have nested try-except blocks in Python. This means you can have one try-except block inside another try block, and each block can have its own except clauses.\n",
    "\n",
    "Example of nested try-except blocks:\n",
    "\n",
    " Q5\n",
    "Yes, it is possible to have nested try-except blocks in Python. Nesting try-except blocks allows for handling specific exceptions at different levels of code execution. Here's an example:\n",
    "\n",
    "    # Outer try block\n",
    "    outer_variable = 10 / 0  # Raises ZeroDivision Error\n",
    "except Zero Division Error:\n",
    "    print(\"An error occurred in the outer try block.\")\n",
    "    try:\n",
    "        # Inner try block\n",
    "        inner_variable = int(\"abc\")  # Raises Value Error\n",
    "    except Value Error:\n",
    "        print(\"An error occurred in the inner try block.\")\n",
    "In this example, the outer try block attempts to perform a division by zero, which raises a ZeroDivision Error. The corresponding except block handles this exception and prints a message.\n",
    "\n",
    "Inside the except block, there's another try block known as the inner try block. It attempts to convert the string \"abc\" to an integer using the int() function, which raises a ValueError. The inner except block then handles this exception and prints a separate error message.\n",
    "\n",
    "By using nested try-except blocks, you can handle exceptions at different levels of code execution and provide specific error handling for each situation\n",
    " \n",
    "Q6\n",
    "Yes, it is possible to use multiple exception blocks in a programming language that supports exception handling. In many languages, such as Java and Python, you can have multiple catches or except blocks to handle different types of exceptions separately.\n",
    "\n",
    "Here's an example in Java:\n",
    "    // Code that may throw exceptions\n",
    "    int[] arr = {1, 2, 3};\n",
    "    System.out.println(arr[4]); // This will throw an Array Index Out Of Bounds Exception\n",
    "} catch (Array Index Out Of Bounds Exception e) {\n",
    "    System.out.println(\"Array index out of bounds exception occurred.\");\n",
    "} catch (NullPointerException e) {\n",
    "    System.out.println(\"Null pointer exception occurred.\");\n",
    "} catch (Exception e) {\n",
    "    System.out.println(\"An exception occurred.\");\n",
    "}\n",
    "In this example, we have three catch blocks. The first catch block handles the specific exception ArrayIndexOutOfBounds Exception, the second catch block handles the specific exception NullPointerException, and the third catch block handles any other exceptions that are subclasses of Exception. The code within the corresponding catch block will be executed if the corresponding exception is thrown.\n",
    "\n",
    "The order of the catch blocks is important. If an exception is thrown, the program will check the catch blocks from top to bottom and execute the code inside the first matching catch block. Therefore, it's a good practice to order the catch blocks from the most specific exceptions to the more general ones.\n",
    "\n",
    "Similar multiple exception handling can be done in other languages like Python using multiple except blocks with different exception types.\n",
    "\n",
    " Q7\n",
    "a. EOF Error: This error is raised when there is an attempt to read beyond the end of a file or input stream (reaching the end-of-file). It usually occurs when the input stream or file does not contain the expected data or has been closed prematurely.\n",
    "\n",
    "b. Floating Point Error: This error is raised when an arithmetic operation involving floating-point numbers fails. It can occur in situations such as division by zero or when a mathematical function is used with an invalid input.\n",
    "\n",
    "c. Index Error: This error is raised when you try to access an index that is out of range in a sequence (such as a list, tuple, or string). It occurs when you attempt to access an element with an index that does not exist in the sequence.\n",
    "\n",
    "d. Memory Error: This error is raised when an operation fails due to insufficient memory allocation. It typically occurs when a program tries to allocate more memory than the system can provide.\n",
    "\n",
    "e. Overflow Error: This error is raised when the result of an arithmetic operation exceeds the maximum representable value for a numeric type. It occurs when a calculation produces a value that is too large to be stored within the given data type's limits.\n",
    "\n",
    "f. Tab Error: This error is raised when there are inconsistencies or incorrect usage of indentation in Python code. It typically occurs when mixing spaces and tabs for indentation or when the indentation level is not consistent within a block of code.\n",
    "\n",
    "g. Value Error: This error is raised when a function receives an argument of the correct data type but with an invalid value. It occurs when the input value does not match the expected range or format.\n",
    "\n",
    "Here's an example of adding a try-except block to handle a ValueError related to IO:\n",
    "\n",
    "    # Perform some IO operation that may raise a ValueError\n",
    "    user_input = int(input(\"Enter a number: \"))\n",
    "    print(\"User input:\", user_input)\n",
    "except ValueError:\n",
    "    print(\"Invalid input. Please enter a valid number.\")\n",
    "In this example, the int(input(\"Enter a number: \")) statement could raise a ValueError if the user enters something that cannot be converted to an integer. The try-except block catches the ValueError and executes the code within the except block, displaying an error message to the user.\n",
    "\n",
    "\n",
    "Q8\n",
    "a. Program to divide two number\n",
    "    number 1 = float(input(\"Enter the first number: \"))\n",
    "    number 2 = float(input(\"Enter the second number: \"))\n",
    "    result = number 1 / number2\n",
    "    print(\"Result: \", result)\n",
    "except Zero Division Error:\n",
    "    print(\"Error: Division by zero is not allowed.\")\n",
    "except Value Error:\n",
    "    print(\"Error: Please enter valid numbers.\")\n",
    "b. Program to convert a string to an integer\n",
    "    string_num = input(\"Enter a number: \")\n",
    "    num = int(string_num)\n",
    "    print(\"Number:\", num)\n",
    "except Value Error:\n",
    "    print(\"Error: Invalid input. Please enter a valid number.\")\n",
    "c. Program to access an element in a list:\n",
    "\n",
    "    my_list = [1, 2, 3, 4, 5]\n",
    "    index = int(input(\"Enter the index: \"))\n",
    "    value = my_list[index]\n",
    "    print(\"Value at index\", index, \":\", value)\n",
    "except Index Error:\n",
    "    print(\"Error: Index out of range.\")\n",
    "except Value Error:\n",
    "    print(\"Error: Invalid index. Please enter a valid integer.\")\n",
    "d. Program to handle a specific exception:\n",
    "\n",
    "    num = int(input(\"Enter a number: \"))\n",
    "    result = 100 / num\n",
    "    print(\"Result:\", result)\n",
    "except Zero DivisionError:\n",
    "    print(\"Error: Division by zero is not allowed.\")\n",
    "except Value Error:\n",
    "    print(\"Error: Invalid input. Please enter a valid number.\")\n",
    "e. Program to handle any Exception \n",
    "    # Code that may raise an exception\n",
    "    result = 100 / 0\n",
    "    print(\"Result:\", result)\n",
    "except Exception as e:\n",
    "    print(\"An error occurred:\", str(e))\n",
    "In the last example, the except Exception as e block will catch any exception that occurs and print the error message. It is generally recommended to handle specific exceptions whenever possible instead of using a broad except block like this, as it allows for more precise error handling.\n",
    "17\n",
    "18"
   ]
  }
 ],
 "metadata": {
  "kernelspec": {
   "display_name": "Python 3",
   "language": "python",
   "name": "python3"
  },
  "language_info": {
   "codemirror_mode": {
    "name": "ipython",
    "version": 3
   },
   "file_extension": ".py",
   "mimetype": "text/x-python",
   "name": "python",
   "nbconvert_exporter": "python",
   "pygments_lexer": "ipython3",
   "version": "3.6.4"
  }
 },
 "nbformat": 4,
 "nbformat_minor": 5
}
